Traceback (most recent call last):
  File "/Users/mac/anaconda3/lib/python3.11/site-packages/jupyter_cache/executors/utils.py", line 58, in single_nb_execution
    executenb(
  File "/Users/mac/anaconda3/lib/python3.11/site-packages/nbclient/client.py", line 1305, in execute
    return NotebookClient(nb=nb, resources=resources, km=km, **kwargs).execute()
           ^^^^^^^^^^^^^^^^^^^^^^^^^^^^^^^^^^^^^^^^^^^^^^^^^^^^^^^^^^^^^^^^^^^^^
  File "/Users/mac/anaconda3/lib/python3.11/site-packages/jupyter_core/utils/__init__.py", line 173, in wrapped
    return loop.run_until_complete(inner)
           ^^^^^^^^^^^^^^^^^^^^^^^^^^^^^^
  File "/Users/mac/anaconda3/lib/python3.11/asyncio/base_events.py", line 653, in run_until_complete
    return future.result()
           ^^^^^^^^^^^^^^^
  File "/Users/mac/anaconda3/lib/python3.11/site-packages/nbclient/client.py", line 705, in async_execute
    await self.async_execute_cell(
  File "/Users/mac/anaconda3/lib/python3.11/site-packages/nbclient/client.py", line 1058, in async_execute_cell
    await self._check_raise_for_error(cell, cell_index, exec_reply)
  File "/Users/mac/anaconda3/lib/python3.11/site-packages/nbclient/client.py", line 914, in _check_raise_for_error
    raise CellExecutionError.from_cell_and_msg(cell, exec_reply_content)
nbclient.exceptions.CellExecutionError: An error occurred while executing the following cell:
------------------
#返回当日涨停股票DataFrame
def limitupList(date):
    collist=['所属行业','代码','名称','涨跌幅','首次封板时间','最后封板时间','炸板次数','涨停统计','连板数']
    stock_zt_pool_em_df = ak.stock_zt_pool_em(date=date)
    last_hs_10=stock_zt_pool_em_df[collist]
    return last_hs_10

last_hs_10=limitupList(lastday)
last_hs_10
------------------


[0;31m---------------------------------------------------------------------------[0m
[0;31mSSLError[0m                                  Traceback (most recent call last)
[0;31mSSLError[0m: [SSL: UNEXPECTED_EOF_WHILE_READING] EOF occurred in violation of protocol (_ssl.c:1006)

The above exception was the direct cause of the following exception:

[0;31mMaxRetryError[0m                             Traceback (most recent call last)
File [0;32m~/anaconda3/lib/python3.11/site-packages/requests/adapters.py:486[0m, in [0;36mHTTPAdapter.send[0;34m(self, request, stream, timeout, verify, cert, proxies)[0m
[1;32m    485[0m [38;5;28;01mtry[39;00m:
[0;32m--> 486[0m     resp [38;5;241m=[39m conn[38;5;241m.[39murlopen(
[1;32m    487[0m         method[38;5;241m=[39mrequest[38;5;241m.[39mmethod,
[1;32m    488[0m         url[38;5;241m=[39murl,
[1;32m    489[0m         body[38;5;241m=[39mrequest[38;5;241m.[39mbody,
[1;32m    490[0m         headers[38;5;241m=[39mrequest[38;5;241m.[39mheaders,
[1;32m    491[0m         redirect[38;5;241m=[39m[38;5;28;01mFalse[39;00m,
[1;32m    492[0m         assert_same_host[38;5;241m=[39m[38;5;28;01mFalse[39;00m,
[1;32m    493[0m         preload_content[38;5;241m=[39m[38;5;28;01mFalse[39;00m,
[1;32m    494[0m         decode_content[38;5;241m=[39m[38;5;28;01mFalse[39;00m,
[1;32m    495[0m         retries[38;5;241m=[39m[38;5;28mself[39m[38;5;241m.[39mmax_retries,
[1;32m    496[0m         timeout[38;5;241m=[39mtimeout,
[1;32m    497[0m         chunked[38;5;241m=[39mchunked,
[1;32m    498[0m     )
[1;32m    500[0m [38;5;28;01mexcept[39;00m (ProtocolError, [38;5;167;01mOSError[39;00m) [38;5;28;01mas[39;00m err:

File [0;32m~/anaconda3/lib/python3.11/site-packages/urllib3/connectionpool.py:844[0m, in [0;36mHTTPConnectionPool.urlopen[0;34m(self, method, url, body, headers, retries, redirect, assert_same_host, timeout, pool_timeout, release_conn, chunked, body_pos, preload_content, decode_content, **response_kw)[0m
[1;32m    842[0m     new_e [38;5;241m=[39m ProtocolError([38;5;124m"[39m[38;5;124mConnection aborted.[39m[38;5;124m"[39m, new_e)
[0;32m--> 844[0m retries [38;5;241m=[39m retries[38;5;241m.[39mincrement(
[1;32m    845[0m     method, url, error[38;5;241m=[39mnew_e, _pool[38;5;241m=[39m[38;5;28mself[39m, _stacktrace[38;5;241m=[39msys[38;5;241m.[39mexc_info()[[38;5;241m2[39m]
[1;32m    846[0m )
[1;32m    847[0m retries[38;5;241m.[39msleep()

File [0;32m~/anaconda3/lib/python3.11/site-packages/urllib3/util/retry.py:515[0m, in [0;36mRetry.increment[0;34m(self, method, url, response, error, _pool, _stacktrace)[0m
[1;32m    514[0m     reason [38;5;241m=[39m error [38;5;129;01mor[39;00m ResponseError(cause)
[0;32m--> 515[0m     [38;5;28;01mraise[39;00m MaxRetryError(_pool, url, reason) [38;5;28;01mfrom[39;00m [38;5;21;01mreason[39;00m  [38;5;66;03m# type: ignore[arg-type][39;00m
[1;32m    517[0m log[38;5;241m.[39mdebug([38;5;124m"[39m[38;5;124mIncremented Retry for (url=[39m[38;5;124m'[39m[38;5;132;01m%s[39;00m[38;5;124m'[39m[38;5;124m): [39m[38;5;132;01m%r[39;00m[38;5;124m"[39m, url, new_retry)

[0;31mMaxRetryError[0m: HTTPSConnectionPool(host='push2ex.eastmoney.com', port=443): Max retries exceeded with url: /getTopicZTPool?ut=7eea3edcaed734bea9cbfc24409ed989&dpt=wz.ztzt&Pageindex=0&pagesize=10000&sort=fbt%3Aasc&date=20241030&_=1621590489736 (Caused by SSLError(SSLEOFError(8, '[SSL: UNEXPECTED_EOF_WHILE_READING] EOF occurred in violation of protocol (_ssl.c:1006)')))

During handling of the above exception, another exception occurred:

[0;31mSSLError[0m                                  Traceback (most recent call last)
Cell [0;32mIn[12], line 8[0m
[1;32m      5[0m     last_hs_10[38;5;241m=[39mstock_zt_pool_em_df[collist]
[1;32m      6[0m     [38;5;28;01mreturn[39;00m last_hs_10
[0;32m----> 8[0m last_hs_10[38;5;241m=[39mlimitupList(lastday)
[1;32m      9[0m last_hs_10

Cell [0;32mIn[12], line 4[0m, in [0;36mlimitupList[0;34m(date)[0m
[1;32m      2[0m [38;5;28;01mdef[39;00m [38;5;21mlimitupList[39m(date):
[1;32m      3[0m     collist[38;5;241m=[39m[[38;5;124m'[39m[38;5;124m所属行业[39m[38;5;124m'[39m,[38;5;124m'[39m[38;5;124m代码[39m[38;5;124m'[39m,[38;5;124m'[39m[38;5;124m名称[39m[38;5;124m'[39m,[38;5;124m'[39m[38;5;124m涨跌幅[39m[38;5;124m'[39m,[38;5;124m'[39m[38;5;124m首次封板时间[39m[38;5;124m'[39m,[38;5;124m'[39m[38;5;124m最后封板时间[39m[38;5;124m'[39m,[38;5;124m'[39m[38;5;124m炸板次数[39m[38;5;124m'[39m,[38;5;124m'[39m[38;5;124m涨停统计[39m[38;5;124m'[39m,[38;5;124m'[39m[38;5;124m连板数[39m[38;5;124m'[39m]
[0;32m----> 4[0m     stock_zt_pool_em_df [38;5;241m=[39m ak[38;5;241m.[39mstock_zt_pool_em(date[38;5;241m=[39mdate)
[1;32m      5[0m     last_hs_10[38;5;241m=[39mstock_zt_pool_em_df[collist]
[1;32m      6[0m     [38;5;28;01mreturn[39;00m last_hs_10

File [0;32m~/anaconda3/lib/python3.11/site-packages/akshare/stock_feature/stock_ztb_em.py:43[0m, in [0;36mstock_zt_pool_em[0;34m(date)[0m
[1;32m     33[0m url [38;5;241m=[39m [38;5;124m"[39m[38;5;124mhttps://push2ex.eastmoney.com/getTopicZTPool[39m[38;5;124m"[39m
[1;32m     34[0m params [38;5;241m=[39m {
[1;32m     35[0m     [38;5;124m"[39m[38;5;124mut[39m[38;5;124m"[39m: [38;5;124m"[39m[38;5;124m7eea3edcaed734bea9cbfc24409ed989[39m[38;5;124m"[39m,
[1;32m     36[0m     [38;5;124m"[39m[38;5;124mdpt[39m[38;5;124m"[39m: [38;5;124m"[39m[38;5;124mwz.ztzt[39m[38;5;124m"[39m,
[0;32m   (...)[0m
[1;32m     41[0m     [38;5;124m"[39m[38;5;124m_[39m[38;5;124m"[39m: [38;5;124m"[39m[38;5;124m1621590489736[39m[38;5;124m"[39m,
[1;32m     42[0m }
[0;32m---> 43[0m r [38;5;241m=[39m requests[38;5;241m.[39mget(url, params[38;5;241m=[39mparams)
[1;32m     44[0m data_json [38;5;241m=[39m r[38;5;241m.[39mjson()
[1;32m     45[0m [38;5;28;01mif[39;00m data_json[[38;5;124m"[39m[38;5;124mdata[39m[38;5;124m"[39m] [38;5;129;01mis[39;00m [38;5;28;01mNone[39;00m:

File [0;32m~/anaconda3/lib/python3.11/site-packages/requests/api.py:73[0m, in [0;36mget[0;34m(url, params, **kwargs)[0m
[1;32m     62[0m [38;5;28;01mdef[39;00m [38;5;21mget[39m(url, params[38;5;241m=[39m[38;5;28;01mNone[39;00m, [38;5;241m*[39m[38;5;241m*[39mkwargs):
[1;32m     63[0m [38;5;250m    [39m[38;5;124mr[39m[38;5;124;03m"""Sends a GET request.[39;00m
[1;32m     64[0m 
[1;32m     65[0m [38;5;124;03m    :param url: URL for the new :class:`Request` object.[39;00m
[0;32m   (...)[0m
[1;32m     70[0m [38;5;124;03m    :rtype: requests.Response[39;00m
[1;32m     71[0m [38;5;124;03m    """[39;00m
[0;32m---> 73[0m     [38;5;28;01mreturn[39;00m request([38;5;124m"[39m[38;5;124mget[39m[38;5;124m"[39m, url, params[38;5;241m=[39mparams, [38;5;241m*[39m[38;5;241m*[39mkwargs)

File [0;32m~/anaconda3/lib/python3.11/site-packages/requests/api.py:59[0m, in [0;36mrequest[0;34m(method, url, **kwargs)[0m
[1;32m     55[0m [38;5;66;03m# By using the 'with' statement we are sure the session is closed, thus we[39;00m
[1;32m     56[0m [38;5;66;03m# avoid leaving sockets open which can trigger a ResourceWarning in some[39;00m
[1;32m     57[0m [38;5;66;03m# cases, and look like a memory leak in others.[39;00m
[1;32m     58[0m [38;5;28;01mwith[39;00m sessions[38;5;241m.[39mSession() [38;5;28;01mas[39;00m session:
[0;32m---> 59[0m     [38;5;28;01mreturn[39;00m session[38;5;241m.[39mrequest(method[38;5;241m=[39mmethod, url[38;5;241m=[39murl, [38;5;241m*[39m[38;5;241m*[39mkwargs)

File [0;32m~/anaconda3/lib/python3.11/site-packages/requests/sessions.py:589[0m, in [0;36mSession.request[0;34m(self, method, url, params, data, headers, cookies, files, auth, timeout, allow_redirects, proxies, hooks, stream, verify, cert, json)[0m
[1;32m    584[0m send_kwargs [38;5;241m=[39m {
[1;32m    585[0m     [38;5;124m"[39m[38;5;124mtimeout[39m[38;5;124m"[39m: timeout,
[1;32m    586[0m     [38;5;124m"[39m[38;5;124mallow_redirects[39m[38;5;124m"[39m: allow_redirects,
[1;32m    587[0m }
[1;32m    588[0m send_kwargs[38;5;241m.[39mupdate(settings)
[0;32m--> 589[0m resp [38;5;241m=[39m [38;5;28mself[39m[38;5;241m.[39msend(prep, [38;5;241m*[39m[38;5;241m*[39msend_kwargs)
[1;32m    591[0m [38;5;28;01mreturn[39;00m resp

File [0;32m~/anaconda3/lib/python3.11/site-packages/requests/sessions.py:703[0m, in [0;36mSession.send[0;34m(self, request, **kwargs)[0m
[1;32m    700[0m start [38;5;241m=[39m preferred_clock()
[1;32m    702[0m [38;5;66;03m# Send the request[39;00m
[0;32m--> 703[0m r [38;5;241m=[39m adapter[38;5;241m.[39msend(request, [38;5;241m*[39m[38;5;241m*[39mkwargs)
[1;32m    705[0m [38;5;66;03m# Total elapsed time of the request (approximately)[39;00m
[1;32m    706[0m elapsed [38;5;241m=[39m preferred_clock() [38;5;241m-[39m start

File [0;32m~/anaconda3/lib/python3.11/site-packages/requests/adapters.py:517[0m, in [0;36mHTTPAdapter.send[0;34m(self, request, stream, timeout, verify, cert, proxies)[0m
[1;32m    513[0m         [38;5;28;01mraise[39;00m ProxyError(e, request[38;5;241m=[39mrequest)
[1;32m    515[0m     [38;5;28;01mif[39;00m [38;5;28misinstance[39m(e[38;5;241m.[39mreason, _SSLError):
[1;32m    516[0m         [38;5;66;03m# This branch is for urllib3 v1.22 and later.[39;00m
[0;32m--> 517[0m         [38;5;28;01mraise[39;00m SSLError(e, request[38;5;241m=[39mrequest)
[1;32m    519[0m     [38;5;28;01mraise[39;00m [38;5;167;01mConnectionError[39;00m(e, request[38;5;241m=[39mrequest)
[1;32m    521[0m [38;5;28;01mexcept[39;00m ClosedPoolError [38;5;28;01mas[39;00m e:

[0;31mSSLError[0m: HTTPSConnectionPool(host='push2ex.eastmoney.com', port=443): Max retries exceeded with url: /getTopicZTPool?ut=7eea3edcaed734bea9cbfc24409ed989&dpt=wz.ztzt&Pageindex=0&pagesize=10000&sort=fbt%3Aasc&date=20241030&_=1621590489736 (Caused by SSLError(SSLEOFError(8, '[SSL: UNEXPECTED_EOF_WHILE_READING] EOF occurred in violation of protocol (_ssl.c:1006)')))

